<?xml version="1.0"?>
<sdf version="1.9">
  <model name="turtlebot">
    <pose>0 0 0.1 0 0 0</pose>
    
    <link name="base_link">
      <pose>0 0 0 0 0 0</pose>
      <inertial>
        <mass>5.0</mass>
        <inertia>
          <ixx>0.052</ixx>
          <iyy>0.052</iyy>
          <izz>0.1</izz>
        </inertia>
      </inertial>
      
      <visual name="base_visual">
        <geometry>
          <cylinder>
            <radius>0.2</radius>
            <length>0.1</length>
          </cylinder>
        </geometry>
        <material>
          <ambient>0 0 0.8 1</ambient>
          <diffuse>0 0 0.8 1</diffuse>
        </material>
      </visual>
      
      <collision name="base_collision">
        <geometry>
          <cylinder>
            <radius>0.2</radius>
            <length>0.1</length>
          </cylinder>
        </geometry>
      </collision>
    </link>
    
    <link name="left_wheel">
      <pose>0 0.12 -0.025 -1.5708 0 0</pose>
      <inertial>
        <mass>0.5</mass>
        <inertia>
          <ixx>0.00016</ixx>
          <iyy>0.00016</iyy>
          <izz>0.0003</izz>
        </inertia>
      </inertial>
      
      <visual name="left_wheel_visual">
        <geometry>
          <cylinder>
            <radius>0.035</radius>
            <length>0.03</length>
          </cylinder>
        </geometry>
        <material>
          <ambient>0.1 0.1 0.1 1</ambient>
          <diffuse>0.1 0.1 0.1 1</diffuse>
        </material>
      </visual>
      
      <collision name="left_wheel_collision">
        <geometry>
          <cylinder>
            <radius>0.035</radius>
            <length>0.03</length>
          </cylinder>
        </geometry>
      </collision>
    </link>
    
    <link name="right_wheel">
      <pose>0 -0.12 -0.025 -1.5708 0 0</pose>
      <inertial>
        <mass>0.5</mass>
        <inertia>
          <ixx>0.00016</ixx>
          <iyy>0.00016</iyy>
          <izz>0.0003</izz>
        </inertia>
      </inertial>
      
      <visual name="right_wheel_visual">
        <geometry>
          <cylinder>
            <radius>0.035</radius>
            <length>0.03</length>
          </cylinder>
        </geometry>
        <material>
          <ambient>0.1 0.1 0.1 1</ambient>
          <diffuse>0.1 0.1 0.1 1</diffuse>
        </material>
      </visual>
      
      <collision name="right_wheel_collision">
        <geometry>
          <cylinder>
            <radius>0.035</radius>
            <length>0.03</length>
          </cylinder>
        </geometry>
      </collision>
    </link>
    
    <link name="caster_wheel">
      <pose>0.15 0 -0.025 0 0 0</pose>
      <inertial>
        <mass>0.1</mass>
        <inertia>
          <ixx>0.00001</ixx>
          <iyy>0.00001</iyy>
          <izz>0.00001</izz>
        </inertia>
      </inertial>
      
      <visual name="caster_visual">
        <geometry>
          <sphere>
            <radius>0.02</radius>
          </sphere>
        </geometry>
        <material>
          <ambient>0.5 0.5 0.5 1</ambient>
          <diffuse>0.5 0.5 0.5 1</diffuse>
        </material>
      </visual>
      
      <collision name="caster_collision">
        <geometry>
          <sphere>
            <radius>0.02</radius>
          </sphere>
        </geometry>
      </collision>
    </link>
    
    <joint name="left_wheel_joint" type="revolute">
      <parent>base_link</parent>
      <child>left_wheel</child>
      <axis>
        <xyz>0 0 1</xyz>
      </axis>
    </joint>
    
    <joint name="right_wheel_joint" type="revolute">
      <parent>base_link</parent>
      <child>right_wheel</child>
      <axis>
        <xyz>0 0 1</xyz>
      </axis>
    </joint>
    
    <joint name="caster_joint" type="fixed">
      <parent>base_link</parent>
      <child>caster_wheel</child>
    </joint>
    
    <!-- Differential Drive Plugin -->
    <plugin filename="gz-sim-diff-drive-system" name="gz::sim::systems::DiffDrive">
      <left_joint>left_wheel_joint</left_joint>
      <right_joint>right_wheel_joint</right_joint>
      <wheel_separation>0.24</wheel_separation>
      <wheel_radius>0.035</wheel_radius>
      <odom_publish_frequency>50</odom_publish_frequency>
      <topic>cmd_vel</topic>
      <odom_topic>odom</odom_topic>
      <tf_topic>tf</tf_topic>
      <frame_id>odom</frame_id>
      <child_frame_id>base_link</child_frame_id>
    </plugin>
    
    <!-- IMU Sensor -->
    <link name="imu_link">
      <pose>0 0 0.05 0 0 0</pose>
      <sensor name="imu_sensor" type="imu">
        <always_on>true</always_on>
        <update_rate>100</update_rate>
        <topic>imu</topic>
      </sensor>
    </link>
    
    <joint name="imu_joint" type="fixed">
      <parent>base_link</parent>
      <child>imu_link</child>
    </joint>
    
  </model>
</sdf>