<?xml version="1.0"?>
<robot name="turtlebot">
  
  <link name="base_footprint"/>
  
  <link name="base_link">
    <visual>
      <geometry>
        <cylinder length="0.1" radius="0.2"/>
      </geometry>
      <material name="blue">
        <color rgba="0 0 0.8 1"/>
      </material>
    </visual>
    <collision>
      <geometry>
        <cylinder length="0.1" radius="0.2"/>
      </geometry>
    </collision>
    <inertial>
      <mass value="5"/>
      <inertia ixx="0.052" ixy="0" ixz="0" iyy="0.052" iyz="0" izz="0.1"/>
    </inertial>
  </link>
  
  <joint name="base_footprint_joint" type="fixed">
    <parent link="base_footprint"/>
    <child link="base_link"/>
    <origin xyz="0 0 0.05"/>
  </joint>
  
  <link name="wheel_left">
    <visual>
      <geometry>
        <cylinder length="0.03" radius="0.035"/>
      </geometry>
      <material name="black">
        <color rgba="0 0 0 1"/>
      </material>
    </visual>
    <collision>
      <geometry>
        <cylinder length="0.03" radius="0.035"/>
      </geometry>
    </collision>
    <inertial>
      <mass value="0.5"/>
      <inertia ixx="0.00016" ixy="0" ixz="0" iyy="0.00016" iyz="0" izz="0.0003"/>
    </inertial>
  </link>
  
  <joint name="wheel_left_joint" type="continuous">
    <parent link="base_link"/>
    <child link="wheel_left"/>
    <origin xyz="0 0.15 -0.03" rpy="-1.5708 0 0"/>
    <axis xyz="0 0 1"/>
  </joint>
  
  <link name="wheel_right">
    <visual>
      <geometry>
        <cylinder length="0.03" radius="0.035"/>
      </geometry>
      <material name="black">
        <color rgba="0 0 0 1"/>
      </material>
    </visual>
    <collision>
      <geometry>
        <cylinder length="0.03" radius="0.035"/>
      </geometry>
    </collision>
    <inertial>
      <mass value="0.5"/>
      <inertia ixx="0.00016" ixy="0" ixz="0" iyy="0.00016" iyz="0" izz="0.0003"/>
    </inertial>
  </link>
  
  <joint name="wheel_right_joint" type="continuous">
    <parent link="base_link"/>
    <child link="wheel_right"/>
    <origin xyz="0 -0.15 -0.03" rpy="-1.5708 0 0"/>
    <axis xyz="0 0 1"/>
  </joint>
  
  <link name="caster_wheel">
    <visual>
      <geometry>
        <sphere radius="0.02"/>
      </geometry>
      <material name="grey">
        <color rgba="0.5 0.5 0.5 1"/>
      </material>
    </visual>
    <collision>
      <geometry>
        <sphere radius="0.02"/>
      </geometry>
    </collision>
    <inertial>
      <mass value="0.1"/>
      <inertia ixx="0.00002" ixy="0" ixz="0" iyy="0.00002" iyz="0" izz="0.00002"/>
    </inertial>
  </link>
  
  <joint name="caster_wheel_joint" type="fixed">
    <parent link="base_link"/>
    <child link="caster_wheel"/>
    <origin xyz="0.15 0 -0.045"/>
  </joint>
  
  <link name="imu_link">
    <visual>
      <geometry>
        <box size="0.02 0.02 0.01"/>
      </geometry>
      <material name="green">
        <color rgba="0 0.8 0 1"/>
      </material>
    </visual>
    <inertial>
      <mass value="0.01"/>
      <inertia ixx="0.000001" ixy="0" ixz="0" iyy="0.000001" iyz="0" izz="0.000001"/>
    </inertial>
  </link>
  
  <joint name="imu_joint" type="fixed">
    <parent link="base_link"/>
    <child link="imu_link"/>
    <origin xyz="0 0 0.06"/>
  </joint>
  
  <link name="gnss_link">
    <visual>
      <geometry>
        <cylinder length="0.05" radius="0.01"/>
      </geometry>
      <material name="yellow">
        <color rgba="1 1 0 1"/>
      </material>
    </visual>
    <inertial>
      <mass value="0.05"/>
      <inertia ixx="0.00001" ixy="0" ixz="0" iyy="0.00001" iyz="0" izz="0.00001"/>
    </inertial>
  </link>
  
  <joint name="gnss_joint" type="fixed">
    <parent link="base_link"/>
    <child link="gnss_link"/>
    <origin xyz="-0.05 0 0.1"/>
  </joint>
  
  <link name="camera_link">
    <visual>
      <geometry>
        <box size="0.03 0.08 0.03"/>
      </geometry>
      <material name="red">
        <color rgba="0.8 0 0 1"/>
      </material>
    </visual>
    <collision>
      <geometry>
        <box size="0.03 0.08 0.03"/>
      </geometry>
    </collision>
    <inertial>
      <mass value="0.1"/>
      <inertia ixx="0.00001" ixy="0" ixz="0" iyy="0.00001" iyz="0" izz="0.00001"/>
    </inertial>
  </link>
  
  <joint name="camera_joint" type="fixed">
    <parent link="base_link"/>
    <child link="camera_link"/>
    <origin xyz="0.18 0 0.05"/>
  </joint>
  
  <gazebo reference="base_link">
    <material>Gazebo/Blue</material>
  </gazebo>
  
  <gazebo reference="wheel_left">
    <material>Gazebo/Black</material>
  </gazebo>
  
  <gazebo reference="wheel_right">
    <material>Gazebo/Black</material>
  </gazebo>
  
  <gazebo reference="caster_wheel">
    <material>Gazebo/Grey</material>
    <mu1>0.0</mu1>
    <mu2>0.0</mu2>
  </gazebo>
  
  <gazebo reference="imu_link">
    <material>Gazebo/Green</material>
    <sensor name="imu_sensor" type="imu">
      <always_on>true</always_on>
      <update_rate>50</update_rate>
      <visualize>true</visualize>
      <topic>imu/data</topic>
    </sensor>
  </gazebo>
  
  <gazebo reference="gnss_link">
    <material>Gazebo/Yellow</material>
    <sensor name="gnss_sensor" type="gps">
      <always_on>true</always_on>
      <update_rate>1</update_rate>
      <visualize>true</visualize>
      <topic>gnss/fix</topic>
    </sensor>
  </gazebo>
  
  <gazebo reference="camera_link">
    <material>Gazebo/Red</material>
    <sensor type="camera" name="camera">
      <update_rate>30.0</update_rate>
      <camera name="front_camera">
        <horizontal_fov>1.3962634</horizontal_fov>
        <image>
          <width>800</width>
          <height>600</height>
          <format>R8G8B8</format>
        </image>
        <clip>
          <near>0.02</near>
          <far>300</far>
        </clip>
      </camera>
      <visualize>true</visualize>
    </sensor>
  </gazebo>
  
  <gazebo>
    <plugin name="diff_drive_controller" filename="libgazebo_ros_diff_drive.so">
      <update_rate>50</update_rate>
      <left_joint>wheel_left_joint</left_joint>
      <right_joint>wheel_right_joint</right_joint>
      <wheel_separation>0.3</wheel_separation>
      <wheel_diameter>0.07</wheel_diameter>
      <max_wheel_torque>20</max_wheel_torque>
      <max_wheel_acceleration>1.0</max_wheel_acceleration>
      <command_topic>turtlebot/cmd_vel</command_topic>
      <odometry_topic>odom</odometry_topic>
      <odometry_frame>odom</odometry_frame>
      <robot_base_frame>base_footprint</robot_base_frame>
      <publish_odom>true</publish_odom>
      <publish_odom_tf>true</publish_odom_tf>
      <publish_wheel_tf>false</publish_wheel_tf>
    </plugin>
  </gazebo>
  
</robot>